Traceback (most recent call last):
  File "/work/DNAL/shi.cheng/NPP/Satellite_Fusion/npp.py", line 345, in <module>
    main()
  File "/work/DNAL/shi.cheng/NPP/Satellite_Fusion/npp.py", line 338, in main
    run_experiments(config, train_loader, val_loader, eval_loader, input_channel, input_shape, device)
  File "/work/DNAL/shi.cheng/NPP/Satellite_Fusion/npp.py", line 242, in run_experiments
    train_losses, val_losses, best_val_loss = NPP.train_model(train_loader, val_loader,
  File "/work/DNAL/shi.cheng/NPP/Satellite_Fusion/tools/NeuralPointProcess.py", line 87, in train_model
    self.load_best_model(experiment_id, exp_name)
  File "/work/DNAL/shi.cheng/NPP/Satellite_Fusion/tools/NeuralPointProcess.py", line 123, in load_best_model
    self.model.load_state_dict(torch.load(model_file_name))
  File "/home/shi.cheng/anaconda3/envs/npp/lib/python3.9/site-packages/torch/serialization.py", line 998, in load
    with _open_file_like(f, 'rb') as opened_file:
  File "/home/shi.cheng/anaconda3/envs/npp/lib/python3.9/site-packages/torch/serialization.py", line 445, in _open_file_like
    return _open_file(name_or_buffer, mode)
  File "/home/shi.cheng/anaconda3/envs/npp/lib/python3.9/site-packages/torch/serialization.py", line 426, in __init__
    super().__init__(open(name, mode))
FileNotFoundError: [Errno 2] No such file or directory: './history/PinMNIST_random_SM_predicted_param2_lr1e-3/SM_predicted_2.0_1726629864/best_model_NPP.pth'
